[2023-04-15T11:05:59.842+0700] {taskinstance.py:1090} INFO - Dependencies all met for dep_context=non-requeueable deps ti=<TaskInstance: our_first_dag_v5.first_task scheduled__2021-09-19T00:00:00+00:00 [queued]>
[2023-04-15T11:05:59.845+0700] {taskinstance.py:1090} INFO - Dependencies all met for dep_context=requeueable deps ti=<TaskInstance: our_first_dag_v5.first_task scheduled__2021-09-19T00:00:00+00:00 [queued]>
[2023-04-15T11:05:59.846+0700] {taskinstance.py:1288} INFO - 
--------------------------------------------------------------------------------
[2023-04-15T11:05:59.846+0700] {taskinstance.py:1289} INFO - Starting attempt 1 of 6
[2023-04-15T11:05:59.846+0700] {taskinstance.py:1290} INFO - 
--------------------------------------------------------------------------------
[2023-04-15T11:05:59.858+0700] {taskinstance.py:1309} INFO - Executing <Task(BashOperator): first_task> on 2021-09-19 00:00:00+00:00
[2023-04-15T11:05:59.862+0700] {logging_mixin.py:137} WARNING - Exception ignored in: <function _after_fork at 0x7fdfdc27e9d0>
[2023-04-15T11:05:59.863+0700] {logging_mixin.py:137} WARNING - Traceback (most recent call last):
[2023-04-15T11:05:59.864+0700] {logging_mixin.py:137} WARNING -   File "/usr/lib/python3.9/threading.py", line 1510, in _after_fork
[2023-04-15T11:05:59.865+0700] {logging_mixin.py:137} WARNING -     thread._reset_internal_locks(True)
[2023-04-15T11:05:59.865+0700] {logging_mixin.py:137} WARNING -   File "/usr/lib/python3.9/threading.py", line 845, in _reset_internal_locks
[2023-04-15T11:05:59.865+0700] {logging_mixin.py:137} WARNING -     self._started._at_fork_reinit()
[2023-04-15T11:05:59.866+0700] {logging_mixin.py:137} WARNING -   File "/usr/lib/python3.9/threading.py", line 527, in _at_fork_reinit
[2023-04-15T11:05:59.866+0700] {logging_mixin.py:137} WARNING -     self._cond._at_fork_reinit()
[2023-04-15T11:05:59.866+0700] {logging_mixin.py:137} WARNING - KeyboardInterrupt: 
[2023-04-15T11:05:59.868+0700] {standard_task_runner.py:82} INFO - Running: ['airflow', 'tasks', 'run', 'our_first_dag_v5', 'first_task', 'scheduled__2021-09-19T00:00:00+00:00', '--job-id', '157', '--raw', '--subdir', 'DAGS_FOLDER/first_dag.py', '--cfg-path', '/tmp/tmp24men0o_']
[2023-04-15T11:05:59.870+0700] {standard_task_runner.py:83} INFO - Job 157: Subtask first_task
[2023-04-15T11:05:59.960+0700] {standard_task_runner.py:100} ERROR - Failed to execute job 157 for task first_task ([Errno 2] No such file or directory: '/tmp/tmp24men0o_'; 23608)
[2023-04-15T11:06:02.040+0700] {taskinstance.py:1080} INFO - Dependencies not met for <TaskInstance: our_first_dag_v5.first_task scheduled__2021-09-19T00:00:00+00:00 [running]>, dependency 'Task Instance Not Running' FAILED: Task is in the running state
[2023-04-15T11:06:02.043+0700] {taskinstance.py:1080} INFO - Dependencies not met for <TaskInstance: our_first_dag_v5.first_task scheduled__2021-09-19T00:00:00+00:00 [running]>, dependency 'Task Instance State' FAILED: Task is in the 'running' state.
[2023-04-15T11:06:02.043+0700] {local_task_job.py:151} INFO - Task is not able to be run
